Workbook

Sheet swiss_qna
A2: Staatssekretariat für Wirtschaft SECO
A3: Secrétariat d'Etat à l'économie SECO
A4: Segreteria di Stato dell’economia SECO
A5: Secretariat da stadi per l'economia SECO
A6: State Secretariat for Economic Affairs SECO
A8: You may choose the language to label the Swiss GDP and its expenditure components in the dropdown-menu below.
A9: Pages labelled at the end with "_q" contain quarterly data, pages with "_y" contain yearly figures.
A10: Pages labelled at the beginning with "nom" contain figures at current prices, pages with "real" contain values at prices of the preceding year (chained values, reference year 2020), pages with "defl" contain implicit price deflators and those with "gc" contain contributions to real GDP-growth.
A12: Sie können im Dropdown-Menu die Sprache wählen, im welcher Sie das BIP der Schweiz gemäss Verwendungsseite beschriftet haben möchten.
A13: Seiten mit der Endbezeichnung "_q" enthalten Quartalszahlen, diejenigen mit "_y" Jahreszahlen.
A14: Seiten mit der Anfangsbezeichnung "nom" enthalten Werte zu laufenden Preisen, diejenigen mit "real" Werte zu Preisen des Vorjahres (verkettet, Referenzjahr 2020), diejenigen mit "defl" implizite Deflatoren und diejenigen mit "gc" Beiträge zum realen BIP-Wachstum.
A16: Vous pouvez choisir ci-dessous la langue avec laquelle vous souhaitez visualiser le PIB de la Suisse selon l'approche par la dépense.
... A22: Le pagine contrassegnate all'inizio con "nom" contengono dati ai prezzi correnti, pagine con "real" contengono valori ai prezzi dell'anno precedente (serie concatenate, anno di riferimento 2020), pagine con "defl" contengono i deflatori impliciti, pagine con "gc" contengono i contributi alla crescita reale del PIL.

Sheet nom_q
A1: =IF(INDIRECT("beschriftung!"&ADDRESS(beschriftung!$C$1*12+ROW(beschriftung!$A1)-1,COLUMN(beschriftung!A$1)))="","",INDIRECT("beschriftung!"&ADDRESS(beschriftung!$C$1*12+ROW(beschriftung!$A1)-1,COLUMN(beschriftung!A$1)))) -> ESA 2010, Quarterly aggregates of Gross Domestic Product, expenditure approach, raw data
A2: =IF(INDIRECT("beschriftung!"&ADDRESS(beschriftung!$C$1*12+ROW(beschriftung!$A2)-1,COLUMN(beschriftung!A$1)))="","",INDIRECT("beschriftung!"&ADDRESS(beschriftung!$C$1*12+ROW(beschriftung!$A2)-1,COLUMN(beschriftung!A$1)))) -> In Mio. Swiss Francs, at current prices, percentage change to previous year
A3: =IF(INDIRECT("beschriftung!"&ADDRESS(beschriftung!$C$1*12+ROW(beschriftung!$A5)-1,COLUMN(beschriftung!A$1)))="","",INDIRECT("beschriftung!"&ADDRESS(beschriftung!$C$1*12+ROW(beschriftung!$A5)-1,COLUMN(beschriftung!A$1))))
C4: =IF(INDIRECT("beschriftung!"&ADDRESS(beschriftung!$C$1*12+ROW(beschriftung!$A5)-1,COLUMN(beschriftung!C$1)))="","",INDIRECT("beschriftung!"&ADDRESS(beschriftung!$C$1*12+ROW(beschriftung!$A5)-1,COLUMN(beschriftung!C$1)))) -> Gross domestic product
E5: =IF(INDIRECT("beschriftung!"&ADDRESS(beschriftung!$C$1*12+ROW(beschriftung!$A6)-1,COLUMN(beschriftung!E$1)))="","",INDIRECT("beschriftung!"&ADDRESS(beschriftung!$C$1*12+ROW(beschriftung!$A6)-1,COLUMN(beschriftung!E$1)))) -> Internal demand | Y5: =IF(INDIRECT("beschriftung!"&ADDRESS(beschriftung!$C$1*12+ROW(beschriftung!$A6)-1,COLUMN(beschriftung!Y$1)))="","",INDIRECT("beschriftung!"&ADDRESS(beschriftung!$C$1*12+ROW(beschriftung!$A6)-1,COLUMN(beschriftung!Y$1)))) -> Trade balance (goods and services) | AU5: =IF(INDIRECT("beschriftung!"&ADDRESS(beschriftung!$C$1*12+ROW(beschriftung!$A6)-1,COLUMN(beschriftung!AU$1)))="","",INDIRECT("beschriftung!"&ADDRESS(beschriftung!$C$1*12+ROW(beschriftung!$A6)-1,COLUMN(beschriftung!AU$1)))) -> Global demand excluding inventories change, stat. discrepancies and valuables
G6: =IF(INDIRECT("beschriftung!"&ADDRESS(beschriftung!$C$1*12+ROW(beschriftung!$A7)-1,COLUMN(beschriftung!G$1)))="","",INDIRECT("beschriftung!"&ADDRESS(beschriftung!$C$1*12+ROW(beschriftung!$A7)-1,COLUMN(beschriftung!G$1)))) -> Final consumption expenditure | M6: =IF(INDIRECT("beschriftung!"&ADDRESS(beschriftung!$C$1*12+ROW(beschriftung!$A7)-1,COLUMN(beschriftung!M$1)))="","",INDIRECT("beschriftung!"&ADDRESS(beschriftung!$C$1*12+ROW(beschriftung!$A7)-1,COLUMN(beschriftung!M$1)))) -> Gross capital formation | AA6: =IF(INDIRECT("beschriftung!"&ADDRESS(beschriftung!$C$1*12+ROW(beschriftung!$A7)-1,COLUMN(beschriftung!AA$1)))="","",INDIRECT("beschriftung!"&ADDRESS(beschriftung!$C$1*12+ROW(beschriftung!$A7)-1,COLUMN(beschriftung!AA$1)))) -> Exports of goods and services | AK6: =IF(INDIRECT("beschriftung!"&ADDRESS(beschriftung!$C$1*12+ROW(beschriftung!$A7)-1,COLUMN(beschriftung!AK$1)))="","",INDIRECT("beschriftung!"&ADDRESS(beschriftung!$C$1*12+ROW(beschriftung!$A7)-1,COLUMN(beschriftung!AK$1)))) -> Imports of goods and services | AW6: =IF(INDIRECT("beschriftung!"&ADDRESS(beschriftung!$C$1*12+ROW(beschriftung!$A7)-1,COLUMN(beschriftung!AW$1)))="","",INDIRECT("beschriftung!"&ADDRESS(beschriftung!$C$1*12+ROW(beschriftung!$A7)-1,COLUMN(beschriftung!AW$1)))) -> Final domestic demand | AY6: =IF(INDIRECT("beschriftung!"&ADDRESS(beschriftung!$C$1*12+ROW(beschriftung!$A7)-1,COLUMN(beschriftung!AY$1)))="","",INDIRECT("beschriftung!"&ADDRESS(beschriftung!$C$1*12+ROW(beschriftung!$A7)-1,COLUMN(beschriftung!AY$1)))) -> Exports of goods and services (excluding valuables) | BC6: =IF(INDIRECT("beschriftung!"&ADDRESS(beschriftung!$C$1*12+ROW(beschriftung!$A7)-1,COLUMN(beschriftung!BC$1)))="","",INDIRECT("beschriftung!"&ADDRESS(beschriftung!$C$1*12+ROW(beschriftung!$A7)-1,COLUMN(beschriftung!BC$1)))) -> Imports of goods and services (excluding valuables)
I7: =IF(INDIRECT("beschriftung!"&ADDRESS(beschriftung!$C$1*12+ROW(beschriftung!$A8)-1,COLUMN(beschriftung!I$1)))="","",INDIRECT("beschriftung!"&ADDRESS(beschriftung!$C$1*12+ROW(beschriftung!$A8)-1,COLUMN(beschriftung!I$1)))) -> Households and NPISH | K7: =IF(INDIRECT("beschriftung!"&ADDRESS(beschriftung!$C$1*12+ROW(beschriftung!$A8)-1,COLUMN(beschriftung!K$1)))="","",INDIRECT("beschriftung!"&ADDRESS(beschriftung!$C$1*12+ROW(beschriftung!$A8)-1,COLUMN(beschriftung!K$1)))) -> General government | O7: =IF(INDIRECT("beschriftung!"&ADDRESS(beschriftung!$C$1*12+ROW(beschriftung!$A8)-1,COLUMN(beschriftung!O$1)))="","",INDIRECT("beschriftung!"&ADDRESS(beschriftung!$C$1*12+ROW(beschriftung!$A8)-1,COLUMN(beschriftung!O$1)))) -> Gross fixed capital formation | U7: =IF(INDIRECT("beschriftung!"&ADDRESS(beschriftung!$C$1*12+ROW(beschriftung!$A8)-1,COLUMN(beschriftung!U$1)))="","",INDIRECT("beschriftung!"&ADDRESS(beschriftung!$C$1*12+ROW(beschriftung!$A8)-1,COLUMN(beschriftung!U$1)))) -> Changes in inventories and statistical discrepancies | W7: =IF(INDIRECT("beschriftung!"&ADDRESS(beschriftung!$C$1*12+ROW(beschriftung!$A8)-1,COLUMN(beschriftung!W$1)))="","",INDIRECT("beschriftung!"&ADDRESS(beschriftung!$C$1*12+ROW(beschriftung!$A8)-1,COLUMN(beschriftung!W$1)))) -> Acquisitions less disposals of valuables (including non-monetary gold) | AC7: =IF(INDIRECT("beschriftung!"&ADDRESS(beschriftung!$C$1*12+ROW(beschriftung!$A8)-1,COLUMN(beschriftung!AC$1)))="","",INDIRECT("beschriftung!"&ADDRESS(beschriftung!$C$1*12+ROW(beschriftung!$A8)-1,COLUMN(beschriftung!AC$1)))) -> Exports (exp.) of goods | AI7: =IF(INDIRECT("beschriftung!"&ADDRESS(beschriftung!$C$1*12+ROW(beschriftung!$A8)-1,COLUMN(beschriftung!AI$1)))="","",INDIRECT("beschriftung!"&ADDRESS(beschriftung!$C$1*12+ROW(beschriftung!$A8)-1,COLUMN(beschriftung!AI$1)))) -> Exports of services | AM7: =IF(INDIRECT("beschriftung!"&ADDRESS(beschriftung!$C$1*12+ROW(beschriftung!$A8)-1,COLUMN(beschriftung!AM$1)))="","",INDIRECT("beschriftung!"&ADDRESS(beschriftung!$C$1*12+ROW(beschriftung!$A8)-1,COLUMN(beschriftung!AM$1)))) -> Imports (imp.) of goods | AS7: =IF(INDIRECT("beschriftung!"&ADDRESS(beschriftung!$C$1*12+ROW(beschriftung!$A8)-1,COLUMN(beschriftung!AS$1)))="","",INDIRECT("beschriftung!"&ADDRESS(beschriftung!$C$1*12+ROW(beschriftung!$A8)-1,COLUMN(beschriftung!AS$1)))) -> Imports of services | BA7: =IF(INDIRECT("beschriftung!"&ADDRESS(beschriftung!$C$1*12+ROW(beschriftung!$A8)-1,COLUMN(beschriftung!BA$1)))="","",INDIRECT("beschriftung!"&ADDRESS(beschriftung!$C$1*12+ROW(beschriftung!$A8)-1,COLUMN(beschriftung!BA$1)))) -> thereof exports of goods excluding valuables
Q8: =IF(INDIRECT("beschriftung!"&ADDRESS(beschriftung!$C$1*12+ROW(beschriftung!$A9)-1,COLUMN(beschriftung!Q$1)))="","",INDIRECT("beschriftung!"&ADDRESS(beschriftung!$C$1*12+ROW(beschriftung!$A9)-1,COLUMN(beschriftung!Q$1)))) -> Construction | S8: =IF(INDIRECT("beschriftung!"&ADDRESS(beschriftung!$C$1*12+ROW(beschriftung!$A9)-1,COLUMN(beschriftung!S$1)))="","",INDIRECT("beschriftung!"&ADDRESS(beschriftung!$C$1*12+ROW(beschriftung!$A9)-1,COLUMN(beschriftung!S$1)))) -> Fixed assets and software | AE8: =IF(INDIRECT("beschriftung!"&ADDRESS(beschriftung!$C$1*12+ROW(beschriftung!$A9)-1,COLUMN(beschriftung!AE$1)))="","",INDIRECT("beschriftung!"&ADDRESS(beschriftung!$C$1*12+ROW(beschriftung!$A9)-1,COLUMN(beschriftung!AE$1)))) -> thereof exp. of goods excluding non-monetary gold | AG8: =IF(INDIRECT("beschriftung!"&ADDRESS(beschriftung!$C$1*12+ROW(beschriftung!$A9)-1,COLUMN(beschriftung!AG$1)))="","",INDIRECT("beschriftung!"&ADDRESS(beschriftung!$C$1*12+ROW(beschriftung!$A9)-1,COLUMN(beschriftung!AG$1)))) -> thereof exp. of goods excluding valuables and merchanting | AO8: =IF(INDIRECT("beschriftung!"&ADDRESS(beschriftung!$C$1*12+ROW(beschriftung!$A9)-1,COLUMN(beschriftung!AO$1)))="","",INDIRECT("beschriftung!"&ADDRESS(beschriftung!$C$1*12+ROW(beschriftung!$A9)-1,COLUMN(beschriftung!AO$1)))) -> thereof imp. of goods excluding non-monetary gold | AQ8: =IF(INDIRECT("beschriftung!"&ADDRESS(beschriftung!$C$1*12+ROW(beschriftung!$A9)-1,COLUMN(beschriftung!AQ$1)))="","",INDIRECT("beschriftung!"&ADDRESS(beschriftung!$C$1*12+ROW(beschriftung!$A9)-1,COLUMN(beschriftung!AQ$1)))) -> thereof imp. of goods excluding valuables
C11: B1GQ | E11: P3_P5 | G11: P3 | I11: P31_S14_S15 | K11: P3_S13 | M11: P5 | O11: P51G | Q11: P5111_N111_112G | S11: P5111_N113T117G | U11: P52_YA0 | W11: P53 | Y11: B11 | AA11: P6 | AC11: P61 | AE11: P61XF11 | AI11: P62 | AK11: P7 | AM11: P71 | AO11: P71XF11 | AS11: P72 | AU11: P3_P51G_P6 | AW11: P3_P51G
A12: 1980 | B12: 1 | C12: 49949.522 | E12: 53377.882 | G12: 34114.172 | I12: 29329.145 | K12: 4785.0268 | M12: 19263.711 | O12: 15311.825 | Q12: 5993.4116 | S12: 9318.4131 | U12: 1546.7862 | W12: 2405.0998 | Y12: -3428.3608 | AA12: 22690.424 | AC12: 17301.694 | AE12: 12216.417 | AG12: 10833.144 | AI12: 5388.73 | AK12: 26118.785 | AM12: 22332.686 | AO12: 15273.155 | AQ12: 13660.879 | AS12: 3786.0983 | AU12: 65849.712 | AW12: 49425.996 | AY12: 16423.716 | BA12: 11034.986 | BC12: 17446.977
A13: 1980 | B13: 2 | C13: 51718.735 | E13: 53088.697 | G13: 34493.289 | I13: 29571.491 | K13: 4921.7984 | M13: 18595.408 | O13: 16858.367 | Q13: 7541.4991 | S13: 9316.8674 | U13: 1542.6461 | W13: 194.39491 | Y13: -1369.9618 | AA13: 23021.907 | AC13: 17437.254 | AE13: 12440.383 | AG13: 11149.811 | AI13: 5584.6525 | AK13: 24391.869 | AM13: 20005.745 | AO13: 14981.199 | AQ13: 13731.093 | AS13: 4386.1234 | AU13: 68293.305 | AW13: 51351.656 | AY13: 16941.649 | BA13: 11356.997 | BC13: 18117.216
A14: 1980 | B14: 3 | C14: 52002.73 | E14: 51918.6 | G14: 34865.014 | I14: 29856.173 | K14: 5008.8404 | M14: 17053.586 | O14: 16920.854 | Q14: 7747.7931 | S14: 9173.0609 | U14: 1063.6076 | W14: -930.87571 | Y14: 84.130231 | AA14: 24407.625 | AC14: 17966.476 | AE14: 12085.253 | AG14: 10876.17 | AI14: 6441.1494 | AK14: 24323.495 | AM14: 19619.425 | AO14: 14770.61 | AQ14: 13675.1 | AS14: 4704.07 | AU14: 69318.293 | AW14: 51785.868 | AY14: 17532.425 | BA14: 11091.276 | BC14: 18379.171
A15: 1980 | B15: 4 | C15: 54793.818 | E15: 55568.64 | G15: 36483.276 | I15: 31374.417 | K15: 5108.8593 | M15: 19085.364 | O15: 14435.029 | Q15: 4808.8753 | S15: 9626.1537 | U15: 5212.9916 | W15: -562.65692 | Y15: -774.82206 | AA15: 24580.705 | AC15: 19330.718 | AE15: 13366.489 | AG15: 11885.365 | AI15: 5249.9868 | AK15: 25355.527 | AM15: 21020.647 | AO15: 15726.542 | AQ15: 14368.991 | AS15: 4334.8798 | AU15: 68284.697 | AW15: 50918.305 | AY15: 17366.392 | BA15: 12116.405 | BC15: 18703.871
A16: 1981 | B16: 1 | C16: 52977.659 | D16: 0.060623949 | E16: 52852.973 | F16: -0.0098338375 | G16: 36161.29 | H16: 0.060007868 | I16: 30931.21 | J16: 0.054623673 | K16: 5230.0799 | L16: 0.093009527 | M16: 16691.683 | N16: -0.13351675 | O16: 16761.881 | P16: 0.094701744 | Q16: 7135.3293 | R16: 0.19052883 | S16: 9626.5519 | T16: 0.033067733 | U16: 777.39732 | W16: -847.59597 | Y16: 124.68593 | AA16: 25071.567 | AB16: 0.10494044 | AC16: 19110.778 | AD16: 0.10456112 | AE16: 12982.685 | AF16: 0.062724392 | AG16: 11523.117 | AH16: 0.063690988 | AI16: 5960.7887 | AJ16: 0.10615834 | AK16: 24946.881 | AL16: -0.044868226 | AM16: 20716.346 | AN16: -0.072375562 | AO16: 14993.45 | AP16: -0.018313498 | AQ16: 14224.32 | AR16: 0.041244876 | AS16: 4230.5355 | AT16: 0.1173866 | AU16: 70655.117 | AV16: 0.072975331 | AW16: 52923.172 | AX16: 0.070755786 | AY16: 17731.945 | AZ16: 0.079654894 | BA16: 11771.157 | BB16: 0.066712428 | BC16: 18454.855 | BD16: 0.057768085
A17: 1981 | B17: 2 | C17: 55522.014 | D17: 0.073537736 | E17: 55073.209 | F17: 0.037381076 | G17: 37131.589 | H17: 0.076487339 | I17: 31760.266 | J17: 0.074016396 | K17: 5371.3231 | L17: 0.091333429 | M17: 17941.62 | N17: -0.035158536 | O17: 18275.534 | P17: 0.084063166 | Q17: 8381.451 | R17: 0.1113773 | S17: 9894.0833 | T17: 0.061953851 | U17: 1039.45 | W17: -1373.3639 | Y17: 448.80429 | AA17: 26037.892 | AB17: 0.13100502 | AC17: 19808.34 | AD17: 0.13597818 | AE17: 13665.408 | AF17: 0.09847167 | AG17: 12055.619 | AH17: 0.081239819 | AI17: 6229.5517 | AJ17: 0.11547706 | AK17: 25589.088 | AL17: 0.049082716 | AM17: 20701.129 | AN17: 0.034759178 | AO17: 15599.046 | AP17: 0.041241548 | AQ17: 14581.932 | AR17: 0.061964405 | AS17: 4887.9593 | AT17: 0.11441445 | AU17: 73952.455 | AV17: 0.082865367 | AW17: 55407.123 | AX17: 0.078974426 | AY17: 18545.331 | AZ17: 0.094659155 | BA17: 12315.78 | BB17: 0.084422229 | BC17: 19469.891 | BD17: 0.074662403
A18: 1981 | B18: 3 | C18: 56051.232 | D18: 0.077851716 | E18: 56267.643 | F18: 0.083766569 | G18: 37611.005 | H18: 0.078760638 | I18: 32152.956 | J18: 0.076928235 | K18: 5458.0484 | L18: 0.089683038 | M18: 18656.638 | N18: 0.094000888 | O18: 18517.487 | P18: 0.094358914 | Q18: 8450.9974 | R18: 0.090761887 | S18: 10066.49 | T18: 0.097397051 | U18: 326.09405 | W18: -186.94338 | Y18: -216.41097 | AA18: 28182.214 | AB18: 0.15464793 | AC18: 20973.363 | AD18: 0.16736101 | AE18: 13825.796 | AF18: 0.14402204 | AG18: 12120.607 | AH18: 0.11441866 | AI18: 7208.8505 | AJ18: 0.11918698 | AK18: 28398.625 | AL18: 0.16753883 | AM18: 23195.805 | AN18: 0.18228769 | AO18: 15806.379 | AP18: 0.070123611 | AQ18: 14791.516 | AR18: 0.081638534 | AS18: 5202.8203 | AT18: 0.10602526 | AU18: 75719.474 | AV18: 0.092344754 | AW18: 56128.492 | AX18: 0.083857321 | AY18: 19590.982 | AZ18: 0.11741425 | BA18: 12382.131 | BB18: 0.11638475 | BC18: 19994.336 | BD18: 0.087880211
A19: 1981 | B19: 4 | C19: 59242.518 | D19: 0.081189828 | E19: 59457.952 | F19: 0.069991141 | G19: 39253.144 | H19: 0.075921588 | I19: 33672.639 | J19: 0.073251475 | K19: 5580.5052 | L19: 0.092319228 | M19: 20204.808 | N19: 0.058654594 | O19: 15297.362 | P19: 0.059738934 | Q19: 5215.8312 | R19: 0.084625993 | S19: 10081.531 | T19: 0.047306266 | U19: 5325.9801 | W19: -418.53436 | Y19: -215.43393 | AA19: 26587.652 | AB19: 0.081647234 | AC19: 20557.598 | AD19: 0.063467912 | AE19: 14304.692 | AF19: 0.070190685 | AG19: 12854.598 | AH19: 0.081548447 | AI19: 6030.0531 | AJ19: 0.14858442 | AK19: 26803.085 | AL19: 0.05709045 | AM19: 22011.669 | AN19: 0.047145182 | AO19: 15860.16 | AP19: 0.0084963442 | AQ19: 14983.688 | AR19: 0.042779429 | AS19: 4791.416 | AT19: 0.10531693 | AU19: 73691.643 | AV19: 0.079182392 | AW19: 54550.506 | AX19: 0.071333904 | AY19: 19141.136 | AZ19: 0.10219418 | BA19: 13111.083 | BB19: 0.082093481 | BC19: 19775.104 | BD19: 0.057273356
A20: 1982 | B20: 1 | C20: 57055.029 | D20: 0.076963957 | E20: 56665.379 | F20: 0.072132289 | G20: 38668.238 | H20: 0.069326843 | I20: 32953.116 | J20: 0.065367807 | K20: 5715.1226 | L20: 0.092740977 | M20: 17997.14 | N20: 0.078210078 | O20: 17060.528 | P20: 0.01781705 | Q20: 7351.8817 | R20: 0.030349311 | S20: 9708.6468 | T20: 0.0085279711 | U20: 705.06646 | W20: 231.5454 | Y20: 389.65028 | AA20: 25125.498 | AB20: 0.0021510712 | AC20: 18339.545 | AD20: -0.040355942 | AE20: 13400.831 | AF20: 0.032208024 | AG20: 11947.988 | AH20: 0.036871163 | AI20: 6785.9529 | AJ20: 0.13843205 | AK20: 24735.848 | AL20: -0.0084593188 | AM20: 20168.824 | AN20: -0.026429457 | AO20: 14592.219 | AP20: -0.026760458 | AQ20: 13786.168 | AR20: -0.030803006 | AS20: 4567.0237 | AT20: 0.079537955 | AU20: 74703.154 | AV20: 0.057292913 | AW20: 55728.767 | AX20: 0.053012609 | AY20: 18974.387 | AZ20: 0.070068007 | BA20: 12188.434 | BB20: 0.035449182 | BC20: 18353.192 | BD20: -0.0055087757
A21: 1982 | B21: 2 | C21: 59324.427 | D21: 0.068484787 | E21: 59939.517 | F21: 0.088360708 | G21: 39531.06 | H21: 0.064620748 | I21: 33696.693 | J21: 0.060970106 | K21: 5834.3674 | L21: 0.086206742 | M21: 20408.457 | N21: 0.13749242 | O21: 18347.307 | P21: 0.003927247 | Q21: 8251.177 | R21: -0.015543135 | S21: 10096.13 | T21: 0.020420948 | U21: 1285.6367 | W21: 775.51363 | Y21: -615.09018 | AA21: 25087.488 | AB21: -0.036500821 | AC21: 18114.704 | AD21: -0.085501184 | AE21: 13810.526 | AF21: 0.010619373 | AG21: 12408.487 | AH21: 0.029269974 | AI21: 6972.7838 | AJ21: 0.11930748 | AK21: 25702.578 | AL21: 0.0044350946 | AM21: 20590.093 | AN21: -0.0053637488 | AO21: 15100.584 | AP21: -0.031954651 | AQ21: 14339.22 | AR21: -0.016644665 | AS21: 5112.4849 | AT21: 0.045934442 | AU21: 77490.496 | AV21: 0.047842103 | AW21: 57878.367 | AX21: 0.04460155 | AY21: 19612.129 | AZ21: 0.057523769 | BA21: 12639.345 | BB21: 0.026272413 | BC21: 19451.705 | BD21: -0.00093404154
A22: 1982 | B22: 3 | C22: 59074.572 | D22: 0.053938874 | E22: 58853.631 | F22: 0.045958719 | G22: 39983.555 | H22: 0.063081291 | I22: 34077.632 | J22: 0.05985999 | K22: 5905.9235 | L22: 0.082057735 | M22: 18870.076 | N22: 0.011440326 | O22: 18091.596 | P22: -0.022999389 | Q22: 8301.8515 | R22: -0.01764832 | S22: 9789.745 | T22: -0.027491706 | U22: -87.38829 | W22: 865.86788 | Y22: 220.9406 | AA22: 26227.507 | AB22: -0.069359587 | AC22: 18319.937 | AD22: -0.12651412 | AE22: 12942.738 | AF22: -0.063870295 | AG22: 11980.701 | AH22: -0.011542799 | AI22: 7907.5704 | AJ22: 0.096925288 | AK22: 26006.567 | AL22: -0.084231483 | AM22: 20563.73 | AN22: -0.113472 | AO22: 14297.753 | AP22: -0.095444129 | AQ22: 13585.03 | AR22: -0.081566064 | AS22: 5442.8362 | AT22: 0.046131891 | AU22: 78189.826 | AV22: 0.032625067 | AW22: 58075.152 | AX22: 0.034682205 | AY22: 20114.675 | AZ22: 0.026731333 | BA22: 12207.104 | BB22: -0.014135439 | BC22: 19027.866 | BD22: -0.048337178
A23: 1982 | B23: 4 | C23: 61638.11 | D23: 0.040437042 | E23: 61432.631 | F23: 0.03321135 | G23: 41637.118 | H23: 0.060733332 | I23: 35587.426 | J23: 0.056864786 | K23: 6049.692 | L23: 0.084076052 | M23: 19795.513 | N23: -0.020257326 | O23: 15722.015 | P23: 0.027759862 | Q23: 5672.3045 | R23: 0.087516898 | S23: 10049.71 | T23: -0.0031563359 | U23: 4074.4915 | W23: -0.99383635 | Y23: 205.47937 | AA23: 26660.41 | AB23: 0.0027365421 | AC23: 19885.546 | AD23: -0.032691188 | AE23: 14330.536 | AF23: 0.0018066797 | AG23: 12969.484 | AH23: 0.0089373523 | AI23: 6774.8636 | AJ23: 0.12351641 | AK23: 26454.93 | AL23: -0.012989366 | AM23: 21360.536 | AN23: -0.029581263 | AO23: 15663.774 | AP23: -0.012382324 | AQ23: 14671.349 | AR23: -0.020845311 | AS23: 5094.3939 | AT23: 0.063233481 | AU23: 77329.362 | AV23: 0.049364065 | AW23: 57359.133 | AX23: 0.051486725 | AY23: 19970.228 | AZ23: 0.043314675 | BA23: 13195.365 | BB23: 0.0064282678 | BC23: 19765.743 | BD23: -0.00047341044
A24: 1983 | B24: 1 | C24: 59277.027 | D24: 0.038944827 | E24: 60218.675 | F24: 0.062706649 | G24: 41299.978 | H24: 0.068059461 | I24: 35184.502 | J24: 0.067713971 | K24: 6115.4758 | L24: 0.070051541 | M24: 18918.697 | N24: 0.051205723 | O24: 17567.462 | P24: 0.02971385 | Q24: 7345.011 | R24: -0.00093455274 | S24: 10222.452 | T24: 0.052922381 | U24: -218.21226 | W24: 1569.4467 | Y24: -941.64753 | AA24: 25447.678 | AB24: 0.012822825 | AC24: 18000.733 | AD24: -0.018474371 | AE24: 13508.261 | AF24: 0.0080166293 | AG24: 12355.302 | AH24: 0.034090587 | AI24: 7446.9443 | AJ24: 0.097405836 | AK24: 26389.325 | AL24: 0.066845402 | AM24: 21437.117 | AN24: 0.06288385 | AO24: 15347.991 | AP24: 0.051792833 | AQ24: 14439.456 | AR24: 0.047387243 | AS24: 4952.208 | AT24: 0.08434035 | AU24: 78886.904 | AV24: 0.056004996 | AW24: 58867.44 | AX24: 0.056320526 | AY24: 20019.464 | AZ24: 0.055078267 | BA24: 12572.519 | BB24: 0.031512248 | BC24: 19391.665 | BD24: 0.056582685
A25: 1983 | B25: 2 | C25: 60666.89 | D25: 0.022629169 | E25: 61588.187 | F25: 0.027505548 | G25: 41277.565 | H25: 0.044180563 | I25: 35058.161 | J25: 0.040403621 | K25: 6219.4034 | L25: 0.065994489 | M25: 20310.622 | N25: -0.0047938552 | O25: 19330.39 | P25: 0.053581873 | Q25: 8588.0116 | R25: 0.040822615 | S25: 10742.378 | T25: 0.064009523 | U25: -144.88494 | W25: 1125.117 | Y25: -921.29698 | AA25: 25670.539 | AB25: 0.023240712 | AC25: 18224.574 | AD25: 0.0060652727 | AE25: 13898.091 | AF25: 0.0063404185 | AG25: 12505.357 | AH25: 0.0078068002 | AI25: 7445.9643 | AJ25: 0.067861054 | AK25: 26591.836 | AL25: 0.034598003 | AM25: 21382.689 | AN25: 0.038494049 | AO25: 15818.377 | AP25: 0.047534076 | AQ25: 14758.348 | AR25: 0.029229492 | AS25: 5209.1468 | AT25: 0.018907015 | AU25: 80779.27 | AV25: 0.042440999 | AW25: 60607.955 | AX25: 0.047160756 | AY25: 20171.315 | AZ25: 0.028512279 | BA25: 12725.351 | BB25: 0.0068046264 | BC25: 19967.495 | BD25: 0.026516439
A26: 1983 | B26: 3 | C26: 60588.291 | D26: 0.025623865 | E26: 61056.068 | F26: 0.03742227 | G26: 41564.015 | H26: 0.03952773 | I26: 35303.227 | J26: 0.035964789 | K26: 6260.7879 | L26: 0.060086174 | M26: 19492.053 | N26: 0.032961038 | O26: 19026.492 | P26: 0.051675694 | Q26: 8858.7234 | R26: 0.067078034 | S26: 10167.769 | T26: 0.038614277 | U26: -1075.0877 | W26: 1540.6487 | Y26: -467.77707 | AA26: 25722.939 | AB26: -0.01923813 | AC26: 17622.553 | AD26: -0.038066911 | AE26: 13330.107 | AF26: 0.029929445 | AG26: 12216.929 | AH26: 0.019717368 | AI26: 8100.3856 | AJ26: 0.024383621 | AK26: 26190.716 | AL26: 0.0070808833 | AM26: 20768.892 | AN26: 0.0099768622 | AO26: 15092.786 | AP26: 0.055605446 | AQ26: 14047.291 | AR26: 0.034027262 | AS26: 5421.8242 | AT26: -0.0038604947 | AU26: 81132.494 | AV26: 0.037634916 | AW26: 60590.507 | AX26: 0.043312069 | AY26: 20541.987 | AZ26: 0.021243819 | BA26: 12441.601 | BB26: 0.019209905 | BC26: 19469.115 | BD26: 0.023189638
A27: 1983 | B27: 4 | C27: 63722.697 | D27: 0.033819774 | E27: 64983.683 | F27: 0.057804007 | G27: 43282.429 | H27: 0.039515468 | I27: 36974.129 | J27: 0.038966075 | K27: 6308.2999 | L27: 0.042747279 | M27: 21701.255 | N27: 0.096271415 | O27: 17045.865 | P27: 0.084203561 | Q27: 6432.088 | R27: 0.13394617 | S27: 10613.777 | T27: 0.056127604 | U27: 3362.7997 | W27: 1292.5903 | Y27: -1260.9859 | AA27: 26266.638 | AB27: -0.014769907 | AC27: 19237.882 | AD27: -0.032569616 | AE27: 14784.884 | AF27: 0.03170489 | AG27: 13372.076 | AH27: 0.031041514 | AI27: 7028.7565 | AJ27: 0.037475712 | AK27: 27527.624 | AL27: 0.04054796 | AM27: 22234.465 | AN27: 0.040913226 | AO27: 16473.367 | AP27: 0.051685681 | AQ27: 15312.119 | AR27: 0.043674932 | AS27: 5293.1589 | AT27: 0.03901642 | AU27: 80965.176 | AV27: 0.04701725 | AW27: 60328.293 | AX27: 0.051764378 | AY27: 20636.882 | AZ27: 0.033382398 | BA27: 13608.126 | BB27: 0.031280778 | BC27: 20605.278 | BD27: 0.042474254
... A195: 2025 | B195: 4 | C195: 218871.5 | D195: 0.0042451134 | E195: 210061.77 | F195: 0.090250895 | G195: 135805.63 | H195: 0.017690049 | I195: 109492.63 | J195: 0.017756443 | K195: 26313 | L195: 0.017413866 | M195: 74256.132 | N195: 0.25373608 | O195: 58778.431 | P195: 0.010194846 | Q195: 17784.795 | R195: 0.026636236 | S195: 40993.636 | T195: 0.0032245297 | U195: 11185.451 | W195: 4292.2498 | Y195: 8809.7384 | AA195: 169838.97 | AB195: 0.075179931 | AC195: 129180.69 | AD195: 0.12537139 | AE195: 88381.99 | AF195: -0.00077957923 | AG195: 67145.341 | AH195: -0.065598147 | AI195: 40658.286 | AJ195: -0.058267452 | AK195: 161029.24 | AL195: 0.21357592 | AM195: 114717.09 | AN195: 0.33864598 | AO195: 65452.501 | AP195: 0.080739664 | AQ195: 62174.455 | AR195: 0.073279963 | AS195: 46312.145 | AT195: -0.014499151 | AU195: 316172.65 | AV195: -0.0082036806 | AW195: 194584.07 | AX195: 0.015414259 | AY195: 121588.59 | AZ195: -0.043796591 | BA195: 80930.303 | BB195: -0.036357486 | BC195: 108486.6 | BD195: 0.033964917

Sheet real_q
A1: =IF(INDIRECT("beschriftung!"&ADDRESS(beschriftung!$C$1*12+ROW(beschriftung!$A1)-1,COLUMN(beschriftung!A$1)))="","",INDIRECT("beschriftung!"&ADDRESS(beschriftung!$C$1*12+ROW(beschriftung!$A1)-1,COLUMN(beschriftung!A$1)))) -> ESA 2010, Quarterly aggregates of Gross Domestic Product, expenditure approach, raw data
A2: =IF(INDIRECT("beschriftung!"&ADDRESS(beschriftung!$C$1*12+ROW(beschriftung!$A3)-1,COLUMN(beschriftung!A$1)))="","",INDIRECT("beschriftung!"&ADDRESS(beschriftung!$C$1*12+ROW(beschriftung!$A3)-1,COLUMN(beschriftung!A$1)))) -> In Mio. Swiss Francs, at prices of preceding year, chained values, reference year 2020, percentage change to previous year
A3: =IF(INDIRECT("beschriftung!"&ADDRESS(beschriftung!$C$1*12+ROW(beschriftung!$A5)-1,COLUMN(beschriftung!A$1)))="","",INDIRECT("beschriftung!"&ADDRESS(beschriftung!$C$1*12+ROW(beschriftung!$A5)-1,COLUMN(beschriftung!A$1))))
C4: =IF(INDIRECT("beschriftung!"&ADDRESS(beschriftung!$C$1*12+ROW(beschriftung!$A5)-1,COLUMN(beschriftung!C$1)))="","",INDIRECT("beschriftung!"&ADDRESS(beschriftung!$C$1*12+ROW(beschriftung!$A5)-1,COLUMN(beschriftung!C$1)))) -> Gross domestic product
E5: =IF(INDIRECT("beschriftung!"&ADDRESS(beschriftung!$C$1*12+ROW(beschriftung!$A6)-1,COLUMN(beschriftung!E$1)))="","",INDIRECT("beschriftung!"&ADDRESS(beschriftung!$C$1*12+ROW(beschriftung!$A6)-1,COLUMN(beschriftung!E$1)))) -> Internal demand | Y5: =IF(INDIRECT("beschriftung!"&ADDRESS(beschriftung!$C$1*12+ROW(beschriftung!$A6)-1,COLUMN(beschriftung!Y$1)))="","",INDIRECT("beschriftung!"&ADDRESS(beschriftung!$C$1*12+ROW(beschriftung!$A6)-1,COLUMN(beschriftung!Y$1)))) -> Trade balance (goods and services) | AU5: =IF(INDIRECT("beschriftung!"&ADDRESS(beschriftung!$C$1*12+ROW(beschriftung!$A6)-1,COLUMN(beschriftung!AU$1)))="","",INDIRECT("beschriftung!"&ADDRESS(beschriftung!$C$1*12+ROW(beschriftung!$A6)-1,COLUMN(beschriftung!AU$1)))) -> Global demand excluding inventories change, stat. discrepancies and valuables
G6: =IF(INDIRECT("beschriftung!"&ADDRESS(beschriftung!$C$1*12+ROW(beschriftung!$A7)-1,COLUMN(beschriftung!G$1)))="","",INDIRECT("beschriftung!"&ADDRESS(beschriftung!$C$1*12+ROW(beschriftung!$A7)-1,COLUMN(beschriftung!G$1)))) -> Final consumption expenditure | M6: =IF(INDIRECT("beschriftung!"&ADDRESS(beschriftung!$C$1*12+ROW(beschriftung!$A7)-1,COLUMN(beschriftung!M$1)))="","",INDIRECT("beschriftung!"&ADDRESS(beschriftung!$C$1*12+ROW(beschriftung!$A7)-1,COLUMN(beschriftung!M$1)))) -> Gross capital formation | AA6: =IF(INDIRECT("beschriftung!"&ADDRESS(beschriftung!$C$1*12+ROW(beschriftung!$A7)-1,COLUMN(beschriftung!AA$1)))="","",INDIRECT("beschriftung!"&ADDRESS(beschriftung!$C$1*12+ROW(beschriftung!$A7)-1,COLUMN(beschriftung!AA$1)))) -> Exports of goods and services | AK6: =IF(INDIRECT("beschriftung!"&ADDRESS(beschriftung!$C$1*12+ROW(beschriftung!$A7)-1,COLUMN(beschriftung!AK$1)))="","",INDIRECT("beschriftung!"&ADDRESS(beschriftung!$C$1*12+ROW(beschriftung!$A7)-1,COLUMN(beschriftung!AK$1)))) -> Imports of goods and services | AW6: =IF(INDIRECT("beschriftung!"&ADDRESS(beschriftung!$C$1*12+ROW(beschriftung!$A7)-1,COLUMN(beschriftung!AW$1)))="","",INDIRECT("beschriftung!"&ADDRESS(beschriftung!$C$1*12+ROW(beschriftung!$A7)-1,COLUMN(beschriftung!AW$1)))) -> Final domestic demand | AY6: =IF(INDIRECT("beschriftung!"&ADDRESS(beschriftung!$C$1*12+ROW(beschriftung!$A7)-1,COLUMN(beschriftung!AY$1)))="","",INDIRECT("beschriftung!"&ADDRESS(beschriftung!$C$1*12+ROW(beschriftung!$A7)-1,COLUMN(beschriftung!AY$1)))) -> Exports of goods and services (excluding valuables) | BC6: =IF(INDIRECT("beschriftung!"&ADDRESS(beschriftung!$C$1*12+ROW(beschriftung!$A7)-1,COLUMN(beschriftung!BC$1)))="","",INDIRECT("beschriftung!"&ADDRESS(beschriftung!$C$1*12+ROW(beschriftung!$A7)-1,COLUMN(beschriftung!BC$1)))) -> Imports of goods and services (excluding valuables)
I7: =IF(INDIRECT("beschriftung!"&ADDRESS(beschriftung!$C$1*12+ROW(beschriftung!$A8)-1,COLUMN(beschriftung!I$1)))="","",INDIRECT("beschriftung!"&ADDRESS(beschriftung!$C$1*12+ROW(beschriftung!$A8)-1,COLUMN(beschriftung!I$1)))) -> Households and NPISH | K7: =IF(INDIRECT("beschriftung!"&ADDRESS(beschriftung!$C$1*12+ROW(beschriftung!$A8)-1,COLUMN(beschriftung!K$1)))="","",INDIRECT("beschriftung!"&ADDRESS(beschriftung!$C$1*12+ROW(beschriftung!$A8)-1,COLUMN(beschriftung!K$1)))) -> General government | O7: =IF(INDIRECT("beschriftung!"&ADDRESS(beschriftung!$C$1*12+ROW(beschriftung!$A8)-1,COLUMN(beschriftung!O$1)))="","",INDIRECT("beschriftung!"&ADDRESS(beschriftung!$C$1*12+ROW(beschriftung!$A8)-1,COLUMN(beschriftung!O$1)))) -> Gross fixed capital formation | U7: =IF(INDIRECT("beschriftung!"&ADDRESS(beschriftung!$C$1*12+ROW(beschriftung!$A8)-1,COLUMN(beschriftung!U$1)))="","",INDIRECT("beschriftung!"&ADDRESS(beschriftung!$C$1*12+ROW(beschriftung!$A8)-1,COLUMN(beschriftung!U$1)))) -> Changes in inventories and statistical discrepancies | W7: =IF(INDIRECT("beschriftung!"&ADDRESS(beschriftung!$C$1*12+ROW(beschriftung!$A8)-1,COLUMN(beschriftung!W$1)))="","",INDIRECT("beschriftung!"&ADDRESS(beschriftung!$C$1*12+ROW(beschriftung!$A8)-1,COLUMN(beschriftung!W$1)))) -> Acquisitions less disposals of valuables (including non-monetary gold) | AC7: =IF(INDIRECT("beschriftung!"&ADDRESS(beschriftung!$C$1*12+ROW(beschriftung!$A8)-1,COLUMN(beschriftung!AC$1)))="","",INDIRECT("beschriftung!"&ADDRESS(beschriftung!$C$1*12+ROW(beschriftung!$A8)-1,COLUMN(beschriftung!AC$1)))) -> Exports (exp.) of goods | AI7: =IF(INDIRECT("beschriftung!"&ADDRESS(beschriftung!$C$1*12+ROW(beschriftung!$A8)-1,COLUMN(beschriftung!AI$1)))="","",INDIRECT("beschriftung!"&ADDRESS(beschriftung!$C$1*12+ROW(beschriftung!$A8)-1,COLUMN(beschriftung!AI$1)))) -> Exports of services | AM7: =IF(INDIRECT("beschriftung!"&ADDRESS(beschriftung!$C$1*12+ROW(beschriftung!$A8)-1,COLUMN(beschriftung!AM$1)))="","",INDIRECT("beschriftung!"&ADDRESS(beschriftung!$C$1*12+ROW(beschriftung!$A8)-1,COLUMN(beschriftung!AM$1)))) -> Imports (imp.) of goods | AS7: =IF(INDIRECT("beschriftung!"&ADDRESS(beschriftung!$C$1*12+ROW(beschriftung!$A8)-1,COLUMN(beschriftung!AS$1)))="","",INDIRECT("beschriftung!"&ADDRESS(beschriftung!$C$1*12+ROW(beschriftung!$A8)-1,COLUMN(beschriftung!AS$1)))) -> Imports of services | BA7: =IF(INDIRECT("beschriftung!"&ADDRESS(beschriftung!$C$1*12+ROW(beschriftung!$A8)-1,COLUMN(beschriftung!BA$1)))="","",INDIRECT("beschriftung!"&ADDRESS(beschriftung!$C$1*12+ROW(beschriftung!$A8)-1,COLUMN(beschriftung!BA$1)))) -> thereof exports of goods excluding valuables
Q8: =IF(INDIRECT("beschriftung!"&ADDRESS(beschriftung!$C$1*12+ROW(beschriftung!$A9)-1,COLUMN(beschriftung!Q$1)))="","",INDIRECT("beschriftung!"&ADDRESS(beschriftung!$C$1*12+ROW(beschriftung!$A9)-1,COLUMN(beschriftung!Q$1)))) -> Construction | S8: =IF(INDIRECT("beschriftung!"&ADDRESS(beschriftung!$C$1*12+ROW(beschriftung!$A9)-1,COLUMN(beschriftung!S$1)))="","",INDIRECT("beschriftung!"&ADDRESS(beschriftung!$C$1*12+ROW(beschriftung!$A9)-1,COLUMN(beschriftung!S$1)))) -> Fixed assets and software | AE8: =IF(INDIRECT("beschriftung!"&ADDRESS(beschriftung!$C$1*12+ROW(beschriftung!$A9)-1,COLUMN(beschriftung!AE$1)))="","",INDIRECT("beschriftung!"&ADDRESS(beschriftung!$C$1*12+ROW(beschriftung!$A9)-1,COLUMN(beschriftung!AE$1)))) -> thereof exp. of goods excluding non-monetary gold | AG8: =IF(INDIRECT("beschriftung!"&ADDRESS(beschriftung!$C$1*12+ROW(beschriftung!$A9)-1,COLUMN(beschriftung!AG$1)))="","",INDIRECT("beschriftung!"&ADDRESS(beschriftung!$C$1*12+ROW(beschriftung!$A9)-1,COLUMN(beschriftung!AG$1)))) -> thereof exp. of goods excluding valuables and merchanting | AO8: =IF(INDIRECT("beschriftung!"&ADDRESS(beschriftung!$C$1*12+ROW(beschriftung!$A9)-1,COLUMN(beschriftung!AO$1)))="","",INDIRECT("beschriftung!"&ADDRESS(beschriftung!$C$1*12+ROW(beschriftung!$A9)-1,COLUMN(beschriftung!AO$1)))) -> thereof imp. of goods excluding non-monetary gold | AQ8: =IF(INDIRECT("beschriftung!"&ADDRESS(beschriftung!$C$1*12+ROW(beschriftung!$A9)-1,COLUMN(beschriftung!AQ$1)))="","",INDIRECT("beschriftung!"&ADDRESS(beschriftung!$C$1*12+ROW(beschriftung!$A9)-1,COLUMN(beschriftung!AQ$1)))) -> thereof imp. of goods excluding valuables
C11: B1GQ | E11: P3_P5 | G11: P3 | I11: P31_S14_S15 | K11: P3_S13 | M11: P5 | O11: P51G | Q11: P5111_N111_112G | S11: P5111_N113T117G | U11: P52_YA0 | W11: P53 | Y11: B11 | AA11: P6 | AC11: P61 | AE11: P61XF11 | AI11: P62 | AK11: P7 | AM11: P71 | AO11: P71XF11 | AS11: P72 | AU11: P3_P51G_P6 | AW11: P3_P51G
A12: 1980 | B12: 1 | C12: 89202.399 | E12: 92357.382 | G12: 60814.338 | I12: 50068.035 | K12: 10535.181 | M12: 31468.772 | O12: 20462.884 | Q12: 9713.5761 | S12: 11334.433 | AA12: 26200.076 | AC12: 17667.739 | AE12: 13357.215 | AG12: 12475.509 | AI12: 8673.1772 | AK12: 26587.017 | AM12: 21377.174 | AO12: 13558.444 | AQ12: 12525.712 | AS12: 5213.9907 | AU12: 100518.77 | AW12: 80947.185 | AY12: 21695.315 | BA12: 13108.949 | BC12: 18178.392
A13: 1980 | B13: 2 | C13: 91839.7 | E13: 90963.012 | G13: 60954.519 | I13: 50042.452 | K13: 10741.307 | M13: 30010.45 | O13: 22306.056 | Q13: 12014.786 | S13: 11283.842 | AA13: 26912.388 | AC13: 18047.76 | AE13: 13305.687 | AG13: 12559.107 | AI13: 9062.7049 | AK13: 24943.184 | AM13: 19362.38 | AO13: 13038.872 | AQ13: 12324.476 | AS13: 5884.8215 | AU13: 103234.15 | AW13: 83333.965 | AY13: 22122.499 | BA13: 13199.873 | BC13: 18459.329
A14: 1980 | B14: 3 | C14: 91077.899 | E14: 87721.607 | G14: 60916.406 | I14: 49915.605 | K14: 10857.658 | M14: 26994.173 | O14: 22278.056 | Q14: 12338.989 | S14: 11012.279 | AA14: 27963.718 | AC14: 18069.741 | AE14: 13152.381 | AG14: 12479.405 | AI14: 10537.441 | AK14: 24361.273 | AM14: 18523.582 | AO14: 13039.536 | AQ14: 12416.344 | AS14: 6293.7505 | AU14: 104462.54 | AW14: 83264.98 | AY14: 23227.076 | BA14: 13125.104 | BC14: 18872.175
A15: 1980 | B15: 4 | C15: 95603.79 | E15: 93337.065 | G15: 63231.804 | I15: 52086.789 | K15: 10917.06 | M15: 30165.098 | O15: 18701.035 | Q15: 7518.3853 | S15: 11386.866 | AA15: 27605.89 | AC15: 18980.141 | AE15: 14164.268 | AG15: 13097.336 | AI15: 8578.3288 | AK15: 24798.015 | AM15: 19385.905 | AO15: 13480.804 | AQ15: 12543.022 | AS15: 5655.5234 | AU15: 101374.06 | AW15: 81012.242 | AY15: 22384.597 | BA15: 13777.245 | BC15: 18532.853
A16: 1981 | B16: 1 | C16: 90183.601 | D16: 0.010999723 | E16: 86051.538 | F16: -0.068276558 | G16: 61421.521 | H16: 0.0099842205 | I16: 50333.656 | J16: 0.0053052172 | K16: 10942.568 | L16: 0.038669217 | M16: 24964.643 | N16: -0.20668518 | O16: 21103.965 | P16: 0.031328933 | Q16: 10765.542 | R16: 0.10829854 | S16: 11128.156 | T16: -0.018199135 | AA16: 28798.628 | AB16: 0.099181091 | AC16: 19418.117 | AD16: 0.09907198 | AE16: 13791.255 | AF16: 0.032494799 | AG16: 12630.333 | AH16: 0.012410253 | AI16: 9544.909 | AJ16: 0.10050893 | AK16: 24617.61 | AL16: -0.074074018 | AM16: 19375.903 | AN16: -0.093617189 | AO16: 12560.464 | AP16: -0.073605792 | AQ16: 12074.625 | AR16: -0.036012927 | AS16: 5427.3877 | AT16: 0.040927773 | AU16: 102857.66 | AV16: 0.023268212 | AW16: 82291.017 | AX16: 0.016601338 | AY16: 22634.576 | AZ16: 0.043293285 | BA16: 13311.445 | BB16: 0.015447155 | BC16: 17827.487 | BD16: -0.019303464
A17: 1981 | B17: 2 | C17: 93716.463 | D17: 0.020435211 | E17: 88386.639 | F17: -0.028323305 | G17: 61958.844 | H17: 0.016476626 | I17: 50781.396 | J17: 0.014766331 | K17: 11028.725 | L17: 0.026758182 | M17: 26672.617 | N17: -0.11122236 | O17: 22585.689 | P17: 0.012536182 | Q17: 12421.397 | R17: 0.033842506 | S17: 11230.415 | T17: -0.0047347781 | AA17: 30143.463 | AB17: 0.120059 | AC17: 20421.716 | AD17: 0.13153742 | AE17: 14629.804 | AF17: 0.099515184 | AG17: 13122.235 | AH17: 0.044838293 | AI17: 9834.7977 | AJ17: 0.085194524 | AK17: 25160.442 | AL17: 0.00871011 | AM17: 19413.689 | AN17: 0.0026499546 | AO17: 13008.758 | AP17: -0.0023095908 | AQ17: 12135.781 | AR17: -0.015310595 | AS17: 6097.3185 | AT17: 0.036109333 | AU17: 105948.74 | AV17: 0.026295415 | AW17: 84599.599 | AX17: 0.015187487 | AY17: 23448.196 | AZ17: 0.059925267 | BA17: 13828.124 | BB17: 0.047595228 | BC17: 18406.74 | BD17: -0.0028488992
A18: 1981 | B18: 3 | C18: 92951.665 | D18: 0.020573229 | E18: 89214.869 | F18: 0.017022746 | G18: 61637.068 | H18: 0.011830341 | I18: 50474.767 | J18: 0.01120216 | K18: 11026.823 | L18: 0.015580318 | M18: 27745.912 | N18: 0.027848196 | O18: 22677.54 | P18: 0.017931762 | Q18: 12510.82 | R18: 0.013925798 | S18: 11246.731 | T18: 0.02129004 | AA18: 33580.996 | AB18: 0.20087735 | AC18: 22650.926 | AD18: 0.25352798 | AE18: 15202.877 | AF18: 0.15590302 | AG18: 13334.22 | AH18: 0.068498063 | AI18: 11116.774 | AJ18: 0.054978587 | AK18: 29095.168 | AL18: 0.19432052 | AM18: 22777.542 | AN18: 0.22965101 | AO18: 13378.605 | AP18: 0.02600313 | AQ18: 12358.229 | AR18: -0.0046804924 | AS18: 6587.6688 | AT18: 0.046700019 | AU18: 107244.74 | AV18: 0.026633466 | AW18: 84416.404 | AX18: 0.013828424 | AY18: 24723.266 | AZ18: 0.064415751 | BA18: 14043.838 | BB18: 0.069998219 | BC18: 19032.275 | BD18: 0.0084833648
A19: 1981 | B19: 4 | C19: 96760.551 | D19: 0.012099533 | E19: 94570.787 | F19: 0.013217918 | G19: 63725.908 | H19: 0.0078141691 | I19: 52469.429 | J19: 0.007346198 | K19: 11033.805 | L19: 0.010693768 | M19: 30881.991 | N19: 0.023765675 | O19: 18482.387 | P19: -0.011691751 | Q19: 7620.1404 | R19: 0.01353417 | S19: 11110.01 | T19: -0.024313637 | AA19: 32651.693 | AB19: 0.18277994 | AC19: 23030.385 | AD19: 0.21339381 | AE19: 15346.841 | AF19: 0.083489866 | AG19: 13607.502 | AH19: 0.03895195 | AI19: 9189.3434 | AJ19: 0.071227697 | AK19: 29271.867 | AL19: 0.1804117 | AM19: 23176.549 | AN19: 0.19553612 | AO19: 13938.196 | AP19: 0.033929151 | AQ19: 12949.401 | AR19: 0.032398821 | AS19: 6259.3785 | AT19: 0.10677264 | AU19: 102801.47 | AV19: 0.014080657 | AW19: 81197.716 | AX19: 0.0022894667 | AY19: 23472.774 | AZ19: 0.048612744 | BA19: 14313.247 | BB19: 0.038904829 | BC19: 19453.005 | BD19: 0.049649754
A20: 1982 | B20: 1 | C20: 90694.538 | D20: 0.0056655212 | E20: 88608.207 | F20: 0.029710898 | G20: 61745.137 | H20: 0.0052687646 | I20: 50591.347 | J20: 0.0051196523 | K20: 11009.336 | L20: 0.0061016384 | M20: 27077.666 | N20: 0.084640639 | O20: 20276.338 | P20: -0.039216649 | Q20: 10476.565 | R20: -0.026842758 | S20: 10590.624 | T20: -0.048303759 | AA20: 31243.201 | AB20: 0.08488505 | AC20: 21311.327 | AD20: 0.097497111 | AE20: 14592.434 | AF20: 0.058093194 | AG20: 12633.968 | AH20: 0.00028774276 | AI20: 9956.039 | AJ20: 0.043073227 | AK20: 28046.749 | AL20: 0.1392962 | AM20: 22167.832 | AN20: 0.14409283 | AO20: 13156.955 | AP20: 0.047489582 | AQ20: 12146.645 | AR20: 0.0059645877 | AS20: 6072.8861 | AT20: 0.11893354 | AU20: 102534.88 | AV20: -0.0031381286 | AW20: 81569.082 | AX20: -0.0087729451 | AY20: 22936.913 | AZ20: 0.013357274 | BA20: 13285.825 | BB20: -0.0019245972 | BC20: 18399.815 | BD20: 0.0321037
A21: 1982 | B21: 2 | C21: 92530.262 | D21: -0.012657346 | E21: 91764.07 | F21: 0.038212014 | G21: 62041.935 | H21: 0.0013410581 | I21: 50857.942 | J21: 0.0015073804 | K21: 11032.254 | L21: 0.00031995186 | M21: 29764.955 | N21: 0.11593681 | O21: 21563.285 | P21: -0.04526781 | Q21: 11634.695 | R21: -0.063334394 | S21: 10888.287 | T21: -0.030464406 | AA21: 30591.141 | AB21: 0.014851597 | AC21: 20764.738 | AD21: 0.016796935 | AE21: 14858.105 | AF21: 0.015605169 | AG21: 12736.193 | AH21: -0.02941896 | AI21: 9897.7224 | AJ21: 0.0063981689 | AK21: 28373.191 | AL21: 0.12769047 | AM21: 22143.205 | AN21: 0.14059749 | AO21: 13222.165 | AP21: 0.016404924 | AQ21: 12163.666 | AR21: 0.0022976855 | AS21: 6511.9836 | AT21: 0.068007784 | AU21: 104339.57 | AV21: -0.015188205 | AW21: 83426.588 | AX21: -0.013865437 | AY21: 22991.395 | AZ21: -0.01948126 | BA21: 13376.171 | BB21: -0.032683611 | BC21: 18750.343 | BD21: 0.018667252
A22: 1982 | B22: 3 | C22: 90924.24 | D22: -0.021811611 | E22: 88517.022 | F22: -0.0078220978 | G22: 61794.252 | H22: 0.0025501487 | I22: 50610.16 | J22: 0.0026823922 | K22: 11045.555 | L22: 0.0016987174 | M22: 26947.771 | N22: -0.028766074 | O22: 21188.398 | P22: -0.065665953 | Q22: 11745.181 | R22: -0.061198088 | S22: 10461.474 | T22: -0.069820834 | AA22: 30430.323 | AB22: -0.093823079 | AC22: 19796.021 | AD22: -0.1260392 | AE22: 13770.343 | AF22: -0.094227816 | AG22: 12286.185 | AH22: -0.078597389 | AI22: 11107.602 | AJ22: -0.00082505971 | AK22: 27144.571 | AL22: -0.067041982 | AM22: 20670.055 | AN22: -0.092524743 | AO22: 12395.896 | AP22: -0.073453747 | AQ22: 11352.61 | AR22: -0.081372402 | AS22: 6900.3752 | AT22: 0.047468453 | AU22: 104197.87 | AV22: -0.028410388 | AW22: 82737.736 | AX22: -0.019885564 | AY22: 23436.661 | AZ22: -0.052040224 | BA22: 12904.946 | BB22: -0.08109549 | BC22: 18120.497 | BD22: -0.047906943
A23: 1982 | B23: 4 | C23: 94571.097 | D23: -0.02262755 | E23: 91751.514 | F23: -0.029811243 | G23: 63926.193 | H23: 0.0031429188 | I23: 52514.261 | J23: 0.00085443129 | K23: 11224.136 | L23: 0.017249841 | M23: 28046.652 | N23: -0.091812054 | O23: 18306.581 | P23: -0.0095120551 | Q23: 8032.031 | R23: 0.054052888 | S23: 10645.315 | T23: -0.041826683 | AA23: 30431.029 | AB23: -0.068010675 | AC23: 21004.009 | AD23: -0.087987089 | AE23: 15467.268 | AF23: 0.0078469858 | AG23: 13221.311 | AH23: -0.028380795 | AI23: 9335.0903 | AJ23: 0.015860426 | AK23: 26976.367 | AL23: -0.078420014 | AM23: 20906.478 | AN23: -0.097946901 | AO23: 13634.556 | AP23: -0.021784778 | AQ23: 12221.056 | AR23: -0.05624548 | AS23: 6382.4942 | AT23: 0.019668999 | AU23: 102307.07 | AV23: -0.0048093243 | AW23: 81141.305 | AX23: -0.00069474074 | AY23: 23090.059 | AZ23: -0.016304605 | BA23: 13867.572 | BB23: -0.031137189 | BC23: 18717.979 | BD23: -0.037784693
A24: 1983 | B24: 1 | C24: 90386.127 | D24: -0.0034005457 | E24: 89538.426 | F24: 0.010498117 | G24: 63092.818 | H24: 0.021826517 | I24: 51667.373 | J24: 0.02126897 | K24: 11284.181 | L24: 0.024964743 | M24: 26701.153 | N24: -0.013904941 | O24: 20375.671 | P24: 0.0048989597 | Q24: 10384.757 | R24: -0.0087632414 | S24: 10751.103 | T24: 0.015152927 | AA24: 29626.006 | AB24: -0.05176149 | AC24: 19448.626 | AD24: -0.087404297 | AE24: 14778.233 | AF24: 0.012732558 | AG24: 12930.691 | AH24: 0.023486144 | AI24: 10447.999 | AJ24: 0.049413258 | AK24: 27489.682 | AL24: -0.019862092 | AM24: 21403.413 | AN24: -0.034483223 | AO24: 13621.03 | AP24: 0.03527221 | AQ24: 12415.584 | AR24: 0.022141011 | AS24: 6377.9407 | AT24: 0.050232219 | AU24: 104617.13 | AV24: 0.02030776 | AW24: 82928.504 | AX24: 0.016665896 | AY24: 23645.794 | AZ24: 0.030905714 | BA24: 13559.505 | BB24: 0.020599388 | BC24: 18935.628 | BD24: 0.029120601
A25: 1983 | B25: 2 | C25: 92476.622 | D25: -0.00057969777 | E25: 92114.942 | F25: 0.0038236292 | G25: 62578.294 | H25: 0.0086451181 | I25: 51076.894 | J25: 0.0043051578 | K25: 11404.613 | L25: 0.033751894 | M25: 29635.236 | N25: -0.0043581111 | O25: 22336.795 | P25: 0.035871654 | Q25: 12132.219 | R25: 0.042762079 | S25: 11218.573 | T25: 0.030334084 | AA25: 29389.321 | AB25: -0.039286565 | AC25: 19179.883 | AD25: -0.076324354 | AE25: 14618.401 | AF25: -0.016132877 | AG25: 12563.269 | AH25: -0.013577405 | AI25: 10509.225 | AJ25: 0.061782168 | AK25: 27650.081 | AL25: -0.025485673 | AM25: 21382.875 | AN25: -0.034336962 | AO25: 13932.818 | AP25: 0.053747067 | AQ25: 12621.941 | AR25: 0.037675765 | AS25: 6594.2866 | AT25: 0.012638688 | AU25: 105998.02 | AV25: 0.015894788 | AW25: 84851.829 | AX25: 0.017083775 | AY25: 23279.636 | AZ25: 0.012536896 | BA25: 13182.09 | BB25: -0.014509472 | BC25: 19333.651 | BD25: 0.031109155
A26: 1983 | B26: 3 | C26: 92015.746 | D26: 0.012004566 | E26: 90686.05 | F26: 0.024504084 | G26: 62673.221 | H26: 0.014224133 | I26: 51174.585 | J26: 0.011152394 | K26: 11396.525 | L26: 0.031774804 | M26: 28185.035 | N26: 0.045913401 | O26: 21929.527 | P26: 0.034978049 | Q26: 12513.264 | R26: 0.065395539 | S26: 10557.225 | T26: 0.0091527143 | AA26: 29954.14 | AB26: -0.015648317 | AC26: 18960.395 | AD26: -0.042211817 | AE26: 14406.048 | AF26: 0.04616479 | AG26: 12659.244 | AH26: 0.030364103 | AI26: 11461.826 | AJ26: 0.031890177 | AK26: 27470.016 | AL26: 0.011989326 | AM26: 20915.699 | AN26: 0.011884053 | AO26: 13423.994 | AP26: 0.082938601 | AQ26: 12142.866 | AR26: 0.06961005 | AS26: 6955.2741 | AT26: 0.0079559221 | AU26: 106649.03 | AV26: 0.023524089 | AW26: 84441.443 | AX26: 0.020591663 | AY26: 24185.026 | AZ26: 0.031931389 | BA26: 13286.413 | BB26: 0.029559762 | BC26: 19061.291 | BD26: 0.051918771
A27: 1983 | B27: 4 | C27: 96198.056 | D27: 0.017203556 | E27: 96615.64 | F27: 0.053014119 | G27: 64797.946 | H27: 0.013636861 | I27: 53229.311 | J27: 0.013616313 | K27: 11381.135 | L27: 0.013987602 | M27: 31862.012 | N27: 0.1360362 | O27: 19529.533 | P27: 0.066803905 | Q27: 9074.1529 | R27: 0.12974575 | S27: 10971.622 | T27: 0.030652621 | AA27: 30304.336 | AB27: -0.0041632807 | AC27: 20534.08 | AD27: -0.022373301 | AE27: 15495.956 | AF27: 0.0018548059 | AG27: 13417.823 | AH27: 0.014863336 | AI27: 9870.1531 | AJ27: 0.057317364 | AK27: 29081.299 | AL27: 0.078028769 | AM27: 22653.539 | AN27: 0.083565503 | AO27: 14545.874 | AP27: 0.06683886 | AQ27: 13111.772 | AR27: 0.072883686 | AS27: 6733.7946 | AT27: 0.05504124 | AU27: 105224.3 | AV27: 0.028514484 | AW27: 83462.768 | AX27: 0.028610121 | AY27: 23739.672 | AZ27: 0.028133869 | BA27: 14078.343 | BB27: 0.015198806 | BC27: 19996.075 | BD27: 0.068281733
... A195: 2025 | B195: 4 | C195: 205191.95 | D195: 0.007063965 | E195: 196665.9 | F195: 0.067954166 | G195: 127143.93 | H195: 0.012378829 | I195: 103828.36 | J195: 0.014874679 | K195: 23363.178 | L195: 0.0020727344 | M195: 69872.14 | N195: 0.19297124 | O195: 54593.488 | P195: 0.0061968496 | Q195: 15317.197 | R195: 0.017940704 | S195: 39338.985 | T195: 0.0011816247 | AA195: 139079.32 | AB195: 0.0060403848 | AC195: 102570.69 | AD195: 0.030284284 | AE195: 82586.854 | AF195: 0.016600899 | AG195: 67736.032 | AH195: -0.053303777 | AI195: 36545.978 | AJ195: -0.055147528 | AK195: 129793.97 | AL195: 0.096426733 | AM195: 89318.476 | AN195: 0.16735252 | AO195: 63997.703 | AP195: 0.092464269 | AQ195: 61746.468 | AR195: 0.099759874 | AS195: 40556.906 | AT195: -0.031096421 | AU195: 294227.29 | AV195: -0.0053880515 | AW195: 181725.07 | AX195: 0.010480761 | AY195: 112691.99 | AZ195: -0.029417014 | BA195: 76251.668 | BB195: -0.016442904 | BC195: 102145.27 | BD195: 0.042045911

Sheet defl_q
A1: =IF(INDIRECT("beschriftung!"&ADDRESS(beschriftung!$C$1*12+ROW(beschriftung!$A1)-1,COLUMN(beschriftung!A$1)))="","",INDIRECT("beschriftung!"&ADDRESS(beschriftung!$C$1*12+ROW(beschriftung!$A1)-1,COLUMN(beschriftung!A$1)))) -> ESA 2010, Quarterly aggregates of Gross Domestic Product, expenditure approach, raw data
A2: =IF(INDIRECT("beschriftung!"&ADDRESS(beschriftung!$C$1*12+ROW(beschriftung!$A4)-1,COLUMN(beschriftung!A$1)))="","",INDIRECT("beschriftung!"&ADDRESS(beschriftung!$C$1*12+ROW(beschriftung!$A4)-1,COLUMN(beschriftung!A$1)))) -> Implicit chain price indexes, year-on-year growth rates
A3: =IF(INDIRECT("beschriftung!"&ADDRESS(beschriftung!$C$1*12+ROW(beschriftung!$A5)-1,COLUMN(beschriftung!A$1)))="","",INDIRECT("beschriftung!"&ADDRESS(beschriftung!$C$1*12+ROW(beschriftung!$A5)-1,COLUMN(beschriftung!A$1))))
C4: =IF(INDIRECT("beschriftung!"&ADDRESS(beschriftung!$C$1*12+ROW(beschriftung!$A5)-1,COLUMN(beschriftung!C$1)))="","",INDIRECT("beschriftung!"&ADDRESS(beschriftung!$C$1*12+ROW(beschriftung!$A5)-1,COLUMN(beschriftung!C$1)))) -> Gross domestic product
E5: =IF(INDIRECT("beschriftung!"&ADDRESS(beschriftung!$C$1*12+ROW(beschriftung!$A6)-1,COLUMN(beschriftung!E$1)))="","",INDIRECT("beschriftung!"&ADDRESS(beschriftung!$C$1*12+ROW(beschriftung!$A6)-1,COLUMN(beschriftung!E$1)))) -> Internal demand | Y5: =IF(INDIRECT("beschriftung!"&ADDRESS(beschriftung!$C$1*12+ROW(beschriftung!$A6)-1,COLUMN(beschriftung!Y$1)))="","",INDIRECT("beschriftung!"&ADDRESS(beschriftung!$C$1*12+ROW(beschriftung!$A6)-1,COLUMN(beschriftung!Y$1)))) -> Trade balance (goods and services) | AU5: =IF(INDIRECT("beschriftung!"&ADDRESS(beschriftung!$C$1*12+ROW(beschriftung!$A6)-1,COLUMN(beschriftung!AU$1)))="","",INDIRECT("beschriftung!"&ADDRESS(beschriftung!$C$1*12+ROW(beschriftung!$A6)-1,COLUMN(beschriftung!AU$1)))) -> Global demand excluding inventories change, stat. discrepancies and valuables
G6: =IF(INDIRECT("beschriftung!"&ADDRESS(beschriftung!$C$1*12+ROW(beschriftung!$A7)-1,COLUMN(beschriftung!G$1)))="","",INDIRECT("beschriftung!"&ADDRESS(beschriftung!$C$1*12+ROW(beschriftung!$A7)-1,COLUMN(beschriftung!G$1)))) -> Final consumption expenditure | M6: =IF(INDIRECT("beschriftung!"&ADDRESS(beschriftung!$C$1*12+ROW(beschriftung!$A7)-1,COLUMN(beschriftung!M$1)))="","",INDIRECT("beschriftung!"&ADDRESS(beschriftung!$C$1*12+ROW(beschriftung!$A7)-1,COLUMN(beschriftung!M$1)))) -> Gross capital formation | AA6: =IF(INDIRECT("beschriftung!"&ADDRESS(beschriftung!$C$1*12+ROW(beschriftung!$A7)-1,COLUMN(beschriftung!AA$1)))="","",INDIRECT("beschriftung!"&ADDRESS(beschriftung!$C$1*12+ROW(beschriftung!$A7)-1,COLUMN(beschriftung!AA$1)))) -> Exports of goods and services | AK6: =IF(INDIRECT("beschriftung!"&ADDRESS(beschriftung!$C$1*12+ROW(beschriftung!$A7)-1,COLUMN(beschriftung!AK$1)))="","",INDIRECT("beschriftung!"&ADDRESS(beschriftung!$C$1*12+ROW(beschriftung!$A7)-1,COLUMN(beschriftung!AK$1)))) -> Imports of goods and services | AW6: =IF(INDIRECT("beschriftung!"&ADDRESS(beschriftung!$C$1*12+ROW(beschriftung!$A7)-1,COLUMN(beschriftung!AW$1)))="","",INDIRECT("beschriftung!"&ADDRESS(beschriftung!$C$1*12+ROW(beschriftung!$A7)-1,COLUMN(beschriftung!AW$1)))) -> Final domestic demand | AY6: =IF(INDIRECT("beschriftung!"&ADDRESS(beschriftung!$C$1*12+ROW(beschriftung!$A7)-1,COLUMN(beschriftung!AY$1)))="","",INDIRECT("beschriftung!"&ADDRESS(beschriftung!$C$1*12+ROW(beschriftung!$A7)-1,COLUMN(beschriftung!AY$1)))) -> Exports of goods and services (excluding valuables) | BC6: =IF(INDIRECT("beschriftung!"&ADDRESS(beschriftung!$C$1*12+ROW(beschriftung!$A7)-1,COLUMN(beschriftung!BC$1)))="","",INDIRECT("beschriftung!"&ADDRESS(beschriftung!$C$1*12+ROW(beschriftung!$A7)-1,COLUMN(beschriftung!BC$1)))) -> Imports of goods and services (excluding valuables)
I7: =IF(INDIRECT("beschriftung!"&ADDRESS(beschriftung!$C$1*12+ROW(beschriftung!$A8)-1,COLUMN(beschriftung!I$1)))="","",INDIRECT("beschriftung!"&ADDRESS(beschriftung!$C$1*12+ROW(beschriftung!$A8)-1,COLUMN(beschriftung!I$1)))) -> Households and NPISH | K7: =IF(INDIRECT("beschriftung!"&ADDRESS(beschriftung!$C$1*12+ROW(beschriftung!$A8)-1,COLUMN(beschriftung!K$1)))="","",INDIRECT("beschriftung!"&ADDRESS(beschriftung!$C$1*12+ROW(beschriftung!$A8)-1,COLUMN(beschriftung!K$1)))) -> General government | O7: =IF(INDIRECT("beschriftung!"&ADDRESS(beschriftung!$C$1*12+ROW(beschriftung!$A8)-1,COLUMN(beschriftung!O$1)))="","",INDIRECT("beschriftung!"&ADDRESS(beschriftung!$C$1*12+ROW(beschriftung!$A8)-1,COLUMN(beschriftung!O$1)))) -> Gross fixed capital formation | U7: =IF(INDIRECT("beschriftung!"&ADDRESS(beschriftung!$C$1*12+ROW(beschriftung!$A8)-1,COLUMN(beschriftung!U$1)))="","",INDIRECT("beschriftung!"&ADDRESS(beschriftung!$C$1*12+ROW(beschriftung!$A8)-1,COLUMN(beschriftung!U$1)))) -> Changes in inventories and statistical discrepancies | W7: =IF(INDIRECT("beschriftung!"&ADDRESS(beschriftung!$C$1*12+ROW(beschriftung!$A8)-1,COLUMN(beschriftung!W$1)))="","",INDIRECT("beschriftung!"&ADDRESS(beschriftung!$C$1*12+ROW(beschriftung!$A8)-1,COLUMN(beschriftung!W$1)))) -> Acquisitions less disposals of valuables (including non-monetary gold) | AC7: =IF(INDIRECT("beschriftung!"&ADDRESS(beschriftung!$C$1*12+ROW(beschriftung!$A8)-1,COLUMN(beschriftung!AC$1)))="","",INDIRECT("beschriftung!"&ADDRESS(beschriftung!$C$1*12+ROW(beschriftung!$A8)-1,COLUMN(beschriftung!AC$1)))) -> Exports (exp.) of goods | AI7: =IF(INDIRECT("beschriftung!"&ADDRESS(beschriftung!$C$1*12+ROW(beschriftung!$A8)-1,COLUMN(beschriftung!AI$1)))="","",INDIRECT("beschriftung!"&ADDRESS(beschriftung!$C$1*12+ROW(beschriftung!$A8)-1,COLUMN(beschriftung!AI$1)))) -> Exports of services | AM7: =IF(INDIRECT("beschriftung!"&ADDRESS(beschriftung!$C$1*12+ROW(beschriftung!$A8)-1,COLUMN(beschriftung!AM$1)))="","",INDIRECT("beschriftung!"&ADDRESS(beschriftung!$C$1*12+ROW(beschriftung!$A8)-1,COLUMN(beschriftung!AM$1)))) -> Imports (imp.) of goods | AS7: =IF(INDIRECT("beschriftung!"&ADDRESS(beschriftung!$C$1*12+ROW(beschriftung!$A8)-1,COLUMN(beschriftung!AS$1)))="","",INDIRECT("beschriftung!"&ADDRESS(beschriftung!$C$1*12+ROW(beschriftung!$A8)-1,COLUMN(beschriftung!AS$1)))) -> Imports of services | BA7: =IF(INDIRECT("beschriftung!"&ADDRESS(beschriftung!$C$1*12+ROW(beschriftung!$A8)-1,COLUMN(beschriftung!BA$1)))="","",INDIRECT("beschriftung!"&ADDRESS(beschriftung!$C$1*12+ROW(beschriftung!$A8)-1,COLUMN(beschriftung!BA$1)))) -> thereof exports of goods excluding valuables
Q8: =IF(INDIRECT("beschriftung!"&ADDRESS(beschriftung!$C$1*12+ROW(beschriftung!$A9)-1,COLUMN(beschriftung!Q$1)))="","",INDIRECT("beschriftung!"&ADDRESS(beschriftung!$C$1*12+ROW(beschriftung!$A9)-1,COLUMN(beschriftung!Q$1)))) -> Construction | S8: =IF(INDIRECT("beschriftung!"&ADDRESS(beschriftung!$C$1*12+ROW(beschriftung!$A9)-1,COLUMN(beschriftung!S$1)))="","",INDIRECT("beschriftung!"&ADDRESS(beschriftung!$C$1*12+ROW(beschriftung!$A9)-1,COLUMN(beschriftung!S$1)))) -> Fixed assets and software | AE8: =IF(INDIRECT("beschriftung!"&ADDRESS(beschriftung!$C$1*12+ROW(beschriftung!$A9)-1,COLUMN(beschriftung!AE$1)))="","",INDIRECT("beschriftung!"&ADDRESS(beschriftung!$C$1*12+ROW(beschriftung!$A9)-1,COLUMN(beschriftung!AE$1)))) -> thereof exp. of goods excluding non-monetary gold | AG8: =IF(INDIRECT("beschriftung!"&ADDRESS(beschriftung!$C$1*12+ROW(beschriftung!$A9)-1,COLUMN(beschriftung!AG$1)))="","",INDIRECT("beschriftung!"&ADDRESS(beschriftung!$C$1*12+ROW(beschriftung!$A9)-1,COLUMN(beschriftung!AG$1)))) -> thereof exp. of goods excluding valuables and merchanting | AO8: =IF(INDIRECT("beschriftung!"&ADDRESS(beschriftung!$C$1*12+ROW(beschriftung!$A9)-1,COLUMN(beschriftung!AO$1)))="","",INDIRECT("beschriftung!"&ADDRESS(beschriftung!$C$1*12+ROW(beschriftung!$A9)-1,COLUMN(beschriftung!AO$1)))) -> thereof imp. of goods excluding non-monetary gold | AQ8: =IF(INDIRECT("beschriftung!"&ADDRESS(beschriftung!$C$1*12+ROW(beschriftung!$A9)-1,COLUMN(beschriftung!AQ$1)))="","",INDIRECT("beschriftung!"&ADDRESS(beschriftung!$C$1*12+ROW(beschriftung!$A9)-1,COLUMN(beschriftung!AQ$1)))) -> thereof imp. of goods excluding valuables
C11: B1GQ | E11: P3_P5 | G11: P3 | I11: P31_S14_S15 | K11: P3_S13 | M11: P5 | O11: P51G | Q11: P5111_N111_112G | S11: P5111_N113T117G | U11: P52_YA0 | W11: P53 | Y11: B11 | AA11: P6 | AC11: P61 | AE11: P61XF11 | AI11: P62 | AK11: P7 | AM11: P71 | AO11: P71XF11 | AS11: P72 | AU11: P3_P51G_P6 | AW11: P3_P51G
A12: 1980 | B12: 1 | C12: 55.995715 | E12: 57.794928 | G12: 56.095607 | I12: 58.578582 | K12: 45.419502 | M12: 61.215324 | O12: 74.827304 | Q12: 61.701392 | S12: 82.213314 | AA12: 86.604421 | AC12: 97.928172 | AE12: 91.459312 | AG12: 86.835283 | AI12: 62.13098 | AK12: 98.238868 | AM12: 104.46978 | AO12: 112.64682 | AQ12: 109.06269 | AS12: 72.614214 | AU12: 65.509868 | AW12: 61.059562 | AY12: 75.701671 | BA12: 84.17903 | BC12: 95.976456
A13: 1980 | B13: 2 | C13: 56.314138 | E13: 58.36295 | G13: 56.588567 | I13: 59.092809 | K13: 45.821223 | M13: 61.963109 | O13: 75.57753 | Q13: 62.768484 | S13: 82.568223 | AA13: 85.543901 | AC13: 96.617277 | AE13: 93.496738 | AG13: 88.778692 | AI13: 61.622358 | AK13: 97.789715 | AM13: 103.32276 | AO13: 114.89643 | AQ13: 111.41319 | AS13: 74.532819 | AU13: 66.153791 | AW13: 61.62152 | AY13: 76.581082 | BA13: 86.038678 | BC13: 98.146667
A14: 1980 | B14: 3 | C14: 57.09698 | E14: 59.185646 | G14: 57.234194 | I14: 59.813306 | K14: 46.131869 | M14: 63.175063 | O14: 75.953011 | Q14: 62.791148 | S14: 83.298481 | AA14: 87.28319 | AC14: 99.428518 | AE14: 91.886424 | AG14: 87.152953 | AI14: 61.126317 | AK14: 99.844926 | AM14: 105.91593 | AO14: 113.27558 | AQ14: 110.1379 | AS14: 74.741921 | AU14: 66.357083 | AW14: 62.194055 | AY14: 75.482704 | BA14: 84.504288 | BC14: 97.387664
A15: 1980 | B15: 4 | C15: 57.313437 | E15: 59.535448 | G15: 57.697668 | I15: 60.234883 | K15: 46.797024 | M15: 63.26969 | O15: 77.188397 | Q15: 63.961544 | S15: 84.53734 | AA15: 89.041524 | AC15: 101.84707 | AE15: 94.367664 | AG15: 90.746431 | AI15: 61.200578 | AK15: 102.24821 | AM15: 108.43263 | AO15: 116.65878 | AQ15: 114.55765 | AS15: 76.648605 | AU15: 67.359143 | AW15: 62.852606 | AY15: 77.581884 | BA15: 87.945049 | BC15: 100.92278
A16: 1981 | B16: 1 | C16: 58.744227 | D16: 0.049084313 | E16: 61.420137 | F16: 0.062725394 | G16: 58.873974 | H16: 0.049529137 | I16: 61.452342 | J16: 0.049058191 | K16: 47.795725 | L16: 0.052317243 | M16: 66.861291 | N16: 0.092231261 | O16: 79.425271 | P16: 0.061447719 | Q16: 66.279331 | R16: 0.074195068 | S16: 86.506261 | T16: 0.052217175 | AA16: 87.0582 | AB16: 0.0052396757 | AC16: 98.417259 | AD16: 0.004994341 | AE16: 94.137077 | AF16: 0.029278204 | AG16: 91.233675 | AH16: 0.050652129 | AI16: 62.449927 | AJ16: 0.0051334543 | AK16: 101.33754 | AL16: 0.031542254 | AM16: 106.91809 | AN16: 0.023435602 | AO16: 119.3702 | AP16: 0.059685492 | AQ16: 117.80341 | AR16: 0.080144024 | AS16: 77.947915 | AT16: 0.073452575 | AU16: 68.692129 | AV16: 0.048576823 | AW16: 64.31221 | AX16: 0.053270092 | AY16: 78.34008 | AZ16: 0.03485272 | BA16: 88.428844 | BB16: 0.050485417 | BC16: 103.51911 | BD16: 0.078588581
A17: 1981 | B17: 2 | C17: 59.244675 | D17: 0.052039096 | E17: 62.309429 | F17: 0.067619591 | G17: 59.929441 | H17: 0.059037966 | I17: 62.543114 | J17: 0.058387889 | K17: 48.703028 | L17: 0.062892362 | M17: 67.266068 | N17: 0.085582512 | O17: 80.916434 | P17: 0.07064141 | Q17: 67.475914 | R17: 0.074996722 | S17: 88.10078 | T17: 0.067005887 | AA17: 86.379897 | AB17: 0.0097727114 | AC17: 96.996455 | AD17: 0.003924536 | AE17: 93.408003 | AF17: -0.00094906725 | AG17: 91.871687 | AH17: 0.034839388 | AI17: 63.341941 | AJ17: 0.027905165 | AK17: 101.70365 | AL17: 0.040023993 | AM17: 106.63161 | AN17: 0.032024361 | AO17: 119.91188 | AP17: 0.043651957 | AQ17: 120.15651 | AR17: 0.078476522 | AS17: 80.16572 | AT17: 0.075576117 | AU17: 69.800223 | AV17: 0.055120535 | AW17: 65.493364 | AX17: 0.062832668 | AY17: 79.090654 | AZ17: 0.03277013 | BA17: 89.063269 | BB17: 0.035153845 | BC17: 105.77588 | BD17: 0.077732755
A18: 1981 | B18: 3 | C18: 60.301482 | D18: 0.056123839 | E18: 63.069804 | F18: 0.065626677 | G18: 61.020107 | H18: 0.066147747 | I18: 63.701049 | J18: 0.064997957 | K18: 49.497922 | L18: 0.072965888 | M18: 67.241034 | N18: 0.064360372 | O18: 81.655625 | P18: 0.07508082 | Q18: 67.549511 | R18: 0.075780782 | S18: 89.505923 | T18: 0.074520468 | AA18: 83.923104 | AB18: -0.038496373 | AC18: 92.593845 | AD18: -0.068739564 | AE18: 90.941968 | AF18: -0.010278523 | AG18: 90.898506 | AH18: 0.042976772 | AI18: 64.846604 | AJ18: 0.060862271 | AK18: 97.605982 | AL18: -0.022424208 | AM18: 101.8363 | AN18: -0.038517691 | AO18: 118.14669 | AP18: 0.043002287 | AQ18: 119.6896 | AR18: 0.086724941 | AS18: 78.97817 | AT18: 0.056678358 | AU18: 70.604373 | AV18: 0.064006571 | AW18: 66.49003 | AX18: 0.069073716 | AY18: 79.241076 | AZ18: 0.049791163 | BA18: 88.167716 | BB18: 0.043351973 | BC18: 105.05489 | BD18: 0.07872896
